Workbook

Sheet RN- Zonas de Litoral
A2: Elaborado por: Lic. Numa Sebastián Calle Lituma, Esp. Mg. MBA. PhD (c) | H2: Prof. Ronal Chaca Espinoza. Phd | I2: Fuente: Antón; 2016 & Vera Rebollo; 2017
A4: EVALUACIÓN DEL POTENCIAL TURÍSTICO
A5: RECURSOS NATURALES
A6: Zonas de Litoral
A7: Atractivo | D7: Rojo o Ausencia | E7: 0 | H7: Amarillo o Fragilidad | I7: 1 | L7: Verde o Aprovechable | M7: 2
A10: Playas | C10: 0 | D10: Ausencia de playas. | H10: Playas con fuerte erosión y/o contaminacion en el agua. | L10: Playas sin erosión y sin contaminación del agua y con limpieza e higiene en general.
A12: Arrecifes
C13: 0 | D13: Carencia de arrecifes. | H13: Arrecifes con flora y fauna dañada por embarcaciones de motor y la actividad del hombre, así como contaminación del agua. | L13: Zonas de arrecifes con estructura geológica intacta y mínima contaminación del agua.
A15: Cuevas, grutas, cenotes y cavernas
C16: 0 | D16: Ausencia de cuevas, grutas, cenotes y cavernas. | H16: Zonas dañadas en su geología y hábitats, fuerte contaminación de agua y con residuos sólidos. | L16: Zonas conservadas en su geología y hábitats, manteniendo las especies endémicas de flora y fauna.
A18: Flora y fauna
C19: 0 | D19: Ausencia de flora y fauna. | H19: Pérdida o fuerte impacto de hábitats y especies de flora y fauna, así como contaminación del suelo, agua y aire. | L19: Amplia diversidad de especies de flora y fauna endémicas, conservación de los hábitats y mínima contaminación en el suelo y aire.
A21: Áreas para la realización de actividades acuáticas turísticas diversas.
B22: 0 | D22: Sin áreas para la realización de actividades acuáticas diversas. | H22: Fuerte contaminación del agua y espacios para el desarrollo de actividades limitado. | L22: Áreas sin contaminación del agua y con una distribución del espacio a utilizar adecuado.
A24: Áreas desérticas
C25: 0 | D25: Sin áreas desérticas. | H25: Fuerte impacto en las zonas desérticas y contaminación de residuos sólidos e industriales en la zona. | L25: Zonas desérticas que conservan sus hábitats de flora y fauna endémicas, sin contaminación.
D28: Promerio de RN(zl) | E28: =AVERAGE(C10,G10,K10,C13,G13,K13,C16,G16,K16,C19,G19,K19,C22,G22,K22,C25,G25,K25) -> 0

Sheet RN- Zonas de Montaña
A2: Elaborado por: Lic. Numa Sebastián Calle Lituma, Esp. Mg. MBA. PhD (c) | H2: Prof. Ronal Chaca Espinoza. Phd | I2: Fuente: Antón; 2016 & Vera Rebollo; 2017
A4: EVALUACIÓN DEL POTENCIAL TURÍSTICO
A5: RECURSOS NATURALES
A6: Zonas de Montaña
A7: Atractivo | D7: Rojo o Ausencia | E7: 0 | H7: Amarillo o Fragilidad | I7: 1 | L7: Verde o Aprovechable | M7: 2
A9: Montañas
D10: Ausencia de montañas. | G10: 1 | H10: Fuerte erosión y contaminación en las montañas. | L10: Montañas conservadas con mínima contaminación.
A12: Sierras
D13: Ausencia de sierras. | H13: Alta deforestación y progresiva contaminación en las sierras. | K13: 2 | L13: Superficies forestales con abundantes especies y mínima contaminación.
A15: Cañadas
D16: Ausencia de cañadas. | H16: Fuerte erosión y contaminación en las cañadas. | K16: 2 | L16: Cañadas conservadas o restauradas con mínima contaminación.
A18: Cañones
D19: Ausencia de cañones. | H19: Fuerte erosión y contaminación en las cañones. | K19: 2 | L19: Ríos con abundante caudal y mínima contaminación del agua.
A21: Cuevas y Grutas
D22: Ausencia de cuevas y grutas. | G22: 1 | H22: Fuerte deterioro en las cuevas y grutas, y contaminación por la proliferación de residuos sólidos. | L22: Cuevas y grutas conservadas en su estructura geológica natural, sin contaminación, adaptadas y seguras para la actividad turística.
A24: Géisers
D25: Ausencia de géisers. | G25: 1 | H25: Fuerte erosión y contaminación en los géisers. | L25: Géisers que conservan su entorno natural, con mínima contaminación y sin riesgo para los visitantes.
A27: Volcanes
D28: Ausencia de volcanes. | G28: 1 | H28: Fuerte erosión y contaminación en los volcanes. | L28: Volcanes conservados en su estructura geológica natural, sin contaminación, adaptadas y seguras para la actividad turística.
A30: Valles
C31: 0 | D31: Ausencia de valles. | H31: Fuerte erosión y contaminación en los valles. | L31: Valles conservados en su estructura geológica natural, sin contaminación, adaptadas y seguras para la actividad turística.
A33: Bosques
C34: 0 | D34: Ausencia de Bosques | H34: Fuerte deterioro en las zonas de bosques, y contaminación por la proliferación de residuos sólidos. | L34: Bosques con presencia de conservación ambiental vigente y normativa aplicable en el sitio.
A36: Flora y fauna
C37: 0 | D37: Ausencia de Flora y Fauna. | H37: Pérdida de Flora y Fauna por la inmersión de la actividad humana. | L37: Folra y Fauna endémica y manejada con principios de conservación y cuidado.
A39: Áreas desérticas
C40: 0 | D40: Sin áreas desérticas. | H40: Fuerte impacto en las zonas desérticas y contaminación de residuos sólidos e industriales en la zona. | L40: Zonas desérticas que conservan sus hábitats de flora y fauna endémicas, sin contaminación.
D43: Promerio de RN(zm) | E43: =AVERAGE(C10,G10,K10,C13,G13,K13,C16,G16,K16,C19,G19,K19,C25,G25,K25,C28,G28,K28,C31,G31,K31,C34,G34,K34,C37,G37,K37,C22,G22,K22,C40,G40,K40) -> 0.90909091

Sheet RN- Áreas Naturales Protegidas
A2: Elaborado por: Lic. Numa Sebastián Calle Lituma, Esp. Mg. MBA. PhD (c) | H2: Prof. Ronal Chaca Espinoza. Phd | I2: Fuente: Antón; 2016 & Vera Rebollo; 2017
A4: EVALUACIÓN DEL POTENCIAL TURÍSTICO
A5: RECURSOS NATURALES
A6: Áreas Naturales Protegidas
A7: Atractivo | D7: Rojo o Ausencia | E7: 0 | H7: Amarillo o Fragilidad | I7: 1 | L7: Verde o Aprovechable | M7: 2
A9: Reservas Marinas
C10: 0 | D10: Ausencia de Reserva(s) Marina en el Territorio. | H10: Fuerte degradación del ecosistema, pérdida de hábitats para especies endémicas de flora y fauna, evidencia de impactos negativos generados por el hombre y ausencia de un plan de manejo ejecutado. | L10: Reserva(s) Marina que conserva sus ecosistemas, que demuestran un control dentro de los impactos generados por la visitación, que mantienen programas de de conservación y cuidado ambiental activos y un plan de manejo aprobado, vigente y ejecutoriado.
A12: Reserva Geobotánica
C13: 0 | D13: Ausencia Reserva(s) Geobotánica en el territorio. | H13: Fuerte degradación del ecosistema, pérdida de hábitats para especies endémicas de flora y fauna, evidencia de impactos negativos generados por el hombre y ausencia de un plan de manejo ejecutado. | L13: Reserva(s) Geobotánica que conserva sus ecosistemas, que demuestran un control dentro de los impactos generados por la visitación, que mantienen programas de de conservación y cuidado ambiental activos y un plan de manejo aprobado, vigente y ejecutoriado.
A15: Reserva Ecológica
D16: Ausencia de Reserva(s) Ecológica en el territorios. | G16: 1 | H16: Fuerte degradación del ecosistema, pérdida de hábitats para especies endémicas de flora y fauna, evidencia de impactos negativos generados por el hombre y ausencia de un plan de manejo ejecutado. | L16: Reserva(s) Ecológica que conserva sus ecosistemas, que demuestran un control dentro de los impactos generados por la visitación, que mantienen programas de de conservación y cuidado ambiental activos y un plan de manejo aprobado, vigente y ejecutoriado.
A18: Reserva de Producción de Fauna
D19: Ausencia de Reserva(s) de Producción de Fauna en el territorio. | G19: 1 | H19: Fuerte degradación del ecosistema, pérdida de hábitats para especies endémicas de flora y fauna, evidencia de impactos negativos generados por el hombre y ausencia de un plan de manejo ejecutado. | L19: Reserva(s) de Producción de Fauna que conserva sus ecosistemas, que demuestran un control dentro de los impactos generados por la visitación, que mantienen programas de de conservación y cuidado ambiental activos y un plan de manejo aprobado, vigente y ejecutoriado.
A21: Reserva Biológica
D22: Ausencia de Reserva(s) Biológica en el territorio. | G22: 1 | H22: Fuerte degradación del ecosistema, pérdida de hábitats para especies endémicas de flora y fauna, evidencia de impactos negativos generados por el hombre y ausencia de un plan de manejo ejecutado. | L22: Reserva(s) Biológica que conserva sus ecosistemas, que demuestran un control dentro de los impactos generados por la visitación, que mantienen programas de de conservación y cuidado ambiental activos y un plan de manejo aprobado, vigente y ejecutoriado.
A24: Reserva de Vida Silvestre
D25: Ausencia de Reserva(s) de Vida Silvestre en el territorio. | H25: Fuerte degradación del ecosistema, pérdida de hábitats para especies endémicas de flora y fauna, evidencia de impactos negativos generados por el hombre y ausencia de un plan de manejo ejecutado. | K25: 2 | L25: Reserva(s) de Vida Silvestre que conserva sus ecosistemas, que demuestran un control dentro de los impactos generados por la visitación, que mantienen programas de de conservación y cuidado ambiental activos y un plan de manejo aprobado, vigente y ejecutoriado.
A27: Parques Nacionales
D28: Ausencia de Parque(s) Nacional en el territorio. | H28: Fuerte degradación del ecosistema, pérdida de hábitats para especies endémicas de flora y fauna, evidencia de impactos negativos generados por el hombre y ausencia de un plan de manejo ejecutado. | K28: 2 | L28: Parque(s) Nacional que conserva sus ecosistemas, que demuestran un control dentro de los impactos generados por la visitación, que mantienen programas de de conservación y cuidado ambiental activos y un plan de manejo aprobado, vigente y ejecutoriado.
A30: Área Protegida Privada
D31: Ausencia de Área(s) Protegida Privada en el territorios. | H31: Fuerte degradación del ecosistema, pérdida de hábitats para especies endémicas de flora y fauna, evidencia de impactos negativos generados por el hombre y ausencia de un plan de manejo ejecutado. | L31: Área(s) Protegida Privada que conserva sus ecosistemas, que demuestran un control dentro de los impactos generados por la visitación, que mantienen programas de de conservación y cuidado ambiental activos y un plan de manejo aprobado, vigente y ejecutoriado.
A33: Área Protegida Comunitaria
D34: Ausencia de Área(s) Protegida Comunitaria en el territorio. | G34: 1 | H34: Fuerte degradación del ecosistema, pérdida de hábitats para especies endémicas de flora y fauna, evidencia de impactos negativos generados por el hombre y ausencia de un plan de manejo ejecutado. | L34: Área(s) Protegida Comunitaria que conserva sus ecosistemas, que demuestran un control dentro de los impactos generados por la visitación, que mantienen programas de de conservación y cuidado ambiental activos y un plan de manejo aprobado, vigente y ejecutoriado.
A36: Área Nacional de Recreación
C37: 0 | D37: Ausencia de Área(s) Nacional de Recreación en el territorio. | H37: Fuerte degradación del ecosistema, pérdida de hábitats para especies endémicas de flora y fauna, evidencia de impactos negativos generados por el hombre y ausencia de un plan de manejo ejecutado.. | L37: Área(s) Nacional de Recreación que conserva sus ecosistemas, que demuestran un control dentro de los impactos generados por la visitación, que mantienen programas de de conservación y cuidado ambiental activos y un plan de manejo aprobado, vigente y ejecutoriado.
A39: Área Ecológica de Conservación
D40: Ausencia de Área(s) Ecológica en Conservación en el territorio. | H40: Fuerte degradación del ecosistema, pérdida de hábitats para especies endémicas de flora y fauna, evidencia de impactos negativos generados por el hombre y ausencia de un plan de manejo ejecutado. | K40: 2 | L40: Área(s) Ecológica de Conservación que conserva sus ecosistemas, que demuestran un control dentro de los impactos generados por la visitación, que mantienen programas de de conservación y cuidado ambiental activos y un plan de manejo aprobado, vigente y ejecutoriado.
D43: Promerio de RN(ap) | E43: =AVERAGE(C10,G10,K10,C13,G13,K13,C16,G16,K16,C19,G19,K19,C25,G25,K25,C28,G28,K28,C31,G31,K31,C34,G34,K34,C37,G37,K37,C22,G22,K22,C40,G40,K40) -> 1

Sheet RN- Cuerpos de Agua
A2: Elaborado por: Lic. Numa Sebastián Calle Lituma, Esp. Mg. MBA. PhD (c) | H2: Prof. Ronal Chaca Espinoza. Phd | I2: Fuente: Antón; 2016 & Vera Rebollo; 2017
A4: EVALUACIÓN DEL POTENCIAL TURÍSTICO
A5: RECURSOS NATURALES
A6: Cuerpos de Agua
A7: Atractivo | D7: Rojo o Ausencia | E7: 0 | H7: Amarillo o Fragilidad | I7: 1 | L7: Verde o Aprovechable | M7: 2
A9: Lagos y Lagunas
D10: Ausencia de lagos y lagunas. | H10: Pérdida de volumen de agua, proliferación de lirios, líquenes y contaminación. | K10: 2 | L10: Lagos y lagunas sin pérdida de volumen de agua o recuperados, con estrícto control a la proliferación de lirios y líquenes y mínima contaminación.
A12: Ríos y Arroyos
D13: Ausencia de ríos y arroyos. | H13: Pérdida de caudal y contaminación del agua. | K13: 2 | L13: Ríos u arroyos sin pérdida de caudal o recuperado y sin contaminación del agua.
A15: Cascadas y Caídas de Agua
D16: Ausencia de cascadas y caídas de agua. | G16: 1 | H16: Siminución del caudal de agua y contaminación de entorno natural. | L16: Caudal de agua sin disminución o recuperado y mínima contaminación en el entorno natural.
A18: Termas
D19: Ausencia de termas. | G19: 1 | H19: Agotamiento de caudales de aguas termales y minerales por la alta intensidad de la actividad del hombre. | L19: Termas sin pérdida de su caudal de aguas termales y mínima contaminación del entorno natural.
A21: Esteros
D22: Ausencia de esteros. | H22: Fuerte contaminación del agua y pérdida o cambio de especies endémicas. | K22: 2 | L22: Mínima contaminación del agua y del entorno natural así como conservación de flora y fauna endémica.
D25: Promerio de RN(ca) | E25: =AVERAGE(C10,G10,K10,C13,G13,K13,C16,G16,K16,C19,G19,K19,C22,G22,K22) -> 1.6

Sheet RC- Artístico Monumental
A2: Elaborado por: Lic. Numa Sebastián Calle Lituma, Esp. Mg. MBA. PhD (c) | H2: Prof. Ronal Chaca Espinoza. Phd | I2: Fuente: Antón; 2016 & Vera Rebollo; 2017
A4: EVALUACIÓN DEL POTENCIAL TURÍSTICO
A5: RECURSOS CULTURALES
A6: Artístico-Monumental
A7: Atractivo | D7: Rojo o Ausencia | E7: 0 | H7: Amarillo o Fragilidad | I7: 1 | L7: Verde o Aprovechable | M7: 2
A9: Zonas Arqueológicas
D10: Carencia de zonas arqueológicas. | G10: 1 | H10: Zonas con fuerte degradación por elementos naturales y falta de conservación. | L10: Zonas arqueológicas protegidas contra los eventos climáticos y con programas de conservación.
A12: Fósiles
D13: Ausencia de fósiles. | G13: 1 | H13: Zonas con fuerte saqueo de fósiles, sin medidas de resguardo y conservación. | L13: Zonas con fósiles protegidas, con medidas de resguardo y conservación.
A15: Pinturas Rupestres
D16: Sin pinturas rupestres. | G16: 1 | H16: Pinturas dañadas por contaminación y/o por la interacción con el hombre. | L16: Pinturas rupestres conservadas en su conformación original, con actividades de conservación y atención continua.
A18: Ciudades Coloniales
D19: Ausencia de ciudades coloniales. | G19: 1 | H19: Ciudades coloniales con fuerte deterioro de sus bienes inmuebles por descuido y/o abandono. | K19: 2 | L19: Centros históricos, edificios y monumentos así como cascos de haciendas conservados o restaurados y con atención continua para prevenir el deterioro.
A21: Pueblos Antiguos
D22: Sin pueblos antiguos. | H22: Pérdida de la arquitectura vernacula e imagen tradicional por el crecimiento demográfico. | K22: 2 | L22: Atención permanente a la conservación de la línea arquitectónica e imagen de los pueblos antiguos.
A24: Sitios Patrimonio de la Humanidad
D25: Carencia de sitios patrimoniales de la humanidad. | H25: Pérdida de la línea arquitectónica, imagen y traza del sitio. | K25: 2 | L25: Sitios conservados o restaurados con atención continua de protección y autenticidad.
A27: Santuarios
D28: Ausencia de Santuarios. | H28: Fuerte deterioro del sitio por la gran intensidad de las visitas religiosas y turísticas. | K28: 2 | L28: Santuarios con medidas de protección y restauración permanente ante el desgaste extraordinario ocasionado por la alta intensidad de visitas.
D31: Promerio de RC(am) | E31: =AVERAGE(C10,G10,K10,C13,G13,K13,C16,G16,K16,C19,G19,K19,C25,G25,K25,C28,G28,K28,C22,G22,K22) -> 1.5

Sheet RC- Nacionalidades y Pueblos
A2: Elaborado por: Lic. Numa Sebastián Calle Lituma, Esp. Mg. MBA. PhD (c) | H2: Prof. Ronal Chaca Espinoza. Phd | I2: Fuente: Antón; 2016 & Vera Rebollo; 2017
A4: EVALUACIÓN DEL POTENCIAL TURÍSTICO
A5: RECURSOS CULTURALES
A6: Nacionalidades y Pueblos Indígenas
A7: Atractivo | D7: Rojo o Ausencia | E7: 0 | H7: Amarillo o Fragilidad | I7: 1 | L7: Verde o Aprovechable | M7: 2
A9: Grupos Étnicos
C10: 0 | D10: Ausencia de grupos étnicos. | H10: Fuerte pérdida de formas de vida, usos, costumbres, lenguajes nativos y aumento de la transculturalización. | L10: Grupos étnicos que conservan sus formas de vida, usos, costumbres autóctonas, así como su lenguaje nativo en sus distintas actividades.
A12: Expresiones Artísticas Folklóricas (Música y danza, Gastronomía, Artesanías Populares)
D13: Inexistencia de expresiones artísticas y/o folklóricas. | G13: 1 | H13: Pérdida progresiva de expresiones musicales, danzas típicas y gastronomía, así como artesanías tradicionales. | L13: Expresiones artísticas y folklóricas intactas, auténticas o rescatadas.
A15: Ferias y Mercados Tradicionales
D16: Ausencia de ferias y mercados tradicionales. | H16: Desaparición progresiva de la realización de ferias y mercados típicos. | K16: 2 | L16: Continua realización y autenticidad de ferias típicas y la existencia de mercados tradicionales.
A18: Eventos Folklóricos (carnavales, fiestas populares)
D19: Sin eventos folklóricos. | H19: Suspensión prolongada de eventos folklóricos. | K19: 2 | L19: Realización de eventos tradicionales y especiales.
A21: Eventos Históricos y/o Religiosos
D22: Sin eventos Históricos y/o Religiosos | H22: Pérdida progresiva de la realización de eventos. | K22: 2 | L22: Conservación de eventos históricos y/o religiosos autóctonos.
D25: Promerio de RC(np) | E25: =AVERAGE(C10,G10,K10,C13,G13,K13,C16,G16,K16,C19,G19,K19,C22,G22,K22) -> 1.4

Sheet RC- Expresiones Contemporáneas
A2: Elaborado por: Lic. Numa Sebastián Calle Lituma, Esp. Mg. MBA. PhD (c) | H2: Prof. Ronal Chaca Espinoza. Phd | I2: Fuente: Antón; 2016 & Vera Rebollo; 2017
A4: EVALUACIÓN DEL POTENCIAL TURÍSTICO
A5: RECURSOS CULTURALES
A6: Expresiones Artísticas Contemporáneas
A7: Atractivo | D7: Rojo o Ausencia | E7: 0 | H7: Amarillo o Fragilidad | I7: 1 | L7: Verde o Aprovechable | M7: 2
A9: Obras de Arte
C10: 0 | D10: Carencia de obras de arte. | H10: Fuerte deterioro de las obras por falta de medidas de conservación y el contacto con el público en general. | L10: Atención continua a la prevención de daños, restauración y rescate de las obras de arte.
A12: Centros Científicos y Técnicos
D13: Falta de centros científicos y técnicos. | H13: Restricciones al contacto y convivencia con turistas. | K13: 2 | L13: Apertura y disposición por parte de instituciones para la visita de turistas.
A15: Explotaciones Mineras
D16: Carencia de explotaciones mineras. | H16: Limitadas posibilidades de adecuación de las explotaciones mineras para su aprovechamiento y visita. | K16: 2 | L16: Disposición por parte de instituciones y/o propietarios y condiciones adecuadas para la visita de turistas.
A18: Plantaciones Agropecuarias
D19: Ausencia de plantaciones agropecuarias. | H19: Renuencia, falta de disposición de los propietarios, o condiciones inadecuadas de las plantaciones. | K19: 2 | L19: Apertura y disposición de propietarios e instalaciones adecuadas para la visita de turistas.
A21: Complejos Industriales
D22: Falta de complejos industriales. | H22: Instalaciones inadecuadas para permitir o garantizar la visita de turistas. | K22: 2 | L22: Apertura y disposición de propietarios, así como instalaciones adecuadas para garantizar la seguridad de los visitantes.
D25: Promerio de RC(ec) | E25: =AVERAGE(C10,G10,K10,C13,G13,K13,C16,G16,K16,C19,G19,K19,C22,G22,K22) -> 1.6

Sheet PT- Alojamiento
A2: Elaborado por: Lic. Numa Sebastián Calle Lituma, Esp. Mg. MBA. PhD (c) | H2: Prof. Ronal Chaca Espinoza. Phd | I2: Fuente: Antón; 2016 & Vera Rebollo; 2017
A4: EVALUACIÓN DEL POTENCIAL TURÍSTICO
A5: PLANTA TURÍSTICA
A6: Alojamiento
A7: Atractivo | D7: Rojo o Ausencia | E7: 0 | H7: Amarillo o Fragilidad | I7: 1 | L7: Verde o Aprovechable | M7: 2
A9: Hoteles
D10: Ausencia de hoteles. | G10: 1 | H10: El territorio cuenta con hoteles de dos y tres estrellas, categorizados y catastrados que cumplen con estándares de servicio básico. | L10: El territorio cuenta con hoteles de cuatro y cinco estrellas, categorizados y catastrados adecuadamente, cumpliendo estándares de servicio nacional e internacional, se evidencia la presencia de cadenas nacionales y/o internacionales.
A12: Hostales
D13: Ausencia de hostales. | G13: 1 | H13: El territorio cuenta con hostales de una y dos estrellas, categorizados y catastrados que cumplen con estándares de servicio básico. | L13: El territorio cuenta con hostales de tres estrellas, categorizados y catastrados adecuadamente, cumpliendo estándares de servicio nacional e internacional.
A15: Hosterías
D16: Ausencia de hosterías. | H16: El territorio cuenta con hosterías de tres estrellas, categorizados y catastrados que cumplen con estándares de servicio básico. | K16: 2 | L16: El territorio cuenta con hostales de cuatro y cinco estrellas, categorizados y catastrados adecuadamente, cumpliendo estándares de servicio nacional e internacional.
A18: Haciendas Turísticas
D19: Ausencia de haciendas turísticas. | H19: El territorio cuenta con haciendas turísticas de tres estrellas, categorizados y catastrados que cumplen con estándares de servicio básico. | K19: 2 | L19: El territorio cuenta con haciendas turísticas de cuatro y cinco estrellas, categorizados y catastrados adecuadamente, cumpliendo estándares de servicio nacional e internacional.
A21: Lodges
D22: Ausencia de lodges. | H22: El territorio cuenta con lodges de tres estrellas, categorizados y catastrados que cumplen con estándares de servicio básico. | K22: 2 | L22: El territorio cuenta con lodges de cuatro y cinco estrellas, categorizados y catastrados adecuadamente, cumpliendo estándares de servicio nacional e internacional.
A24: Resorts
D25: Ausencia de Resorts. | G25: 1 | H25: El territorio cuenta con resorts de cuatro estrellas, categorizados y catastrados que cumplen con estándares de servicio básico y forman parte de una marca nacional. | L25: El territorio cuenta con resorts de cinco estrellas, categorizados y catastrados adecuadamente, cumpliendo estándares de servicio nacional e internacional, además forma parte de una cadena internacional.
A27: Refugios
D28: Ausencia de refugios. | G28: 1 | H28: El territorio evidenica espacios de alojamiento no catastrados dentro del Sistema Nacional de Áreas Naturales Protegidas del país. | L28: El territorio cuenta con refugios categorizados y catastrados adecuadamente, cumpliéndo con lo establecido en el marco normativo nacional respectivo.
A30: Campamentos Turísticos
D31: Ausencia de campamentos turísticos. | G31: 1 | H31: El territorio cuenta con espacios adecuados para la generación de campamentos turísticos pero no con el equiámiento, facilidades e infraestructura requerida. | L31: El territorio cuenta con campamentos turísticos categorizados y catastrados adecuadamente, cumpliéndo con lo establecido en el marco normativo nacional respectivo.
A33: Casa de Huéspedes
D34: Ausencia de casa de huéspedes. | H34: El territorio cuenta con viviendas destinadas para brindar alojamiento a los visitantes, pero las mismas no se encuentran catastradas ni categorizadas. | K34: 2 | L34: El territorio cuenta con casas de huéspedes categorizados y catastrados adecuadamente, cumpliéndo con lo establecido en el marco normativo nacional respectivo.
A36: Centro de Turismo Comunitario (Alojamiento)
D37: El territorio no cuenta con un Centro de Turismo Comunitario. | H37: El territorio cuenta con un centro de turismo comunitario que ofrece viviendas destinadas para brindar alojamiento a los visitantes, pero las mismas no se encuentran autorizadas ni catastradas. | K37: 2 | L37: El territorio cuenta con centro de turismo comunitario categorizados y catastrados adecuadamente, que ofrece servicios de alojamiento, cumpliéndo con lo establecido en el marco normativo nacional respectivo.
D40: Promerio de PT(a) | E40: =AVERAGE(C10,G10,K10,C13,G13,K13,C16,G16,K16,C19,G19,K19,C28,G28,K28,C31,G31,K31,C37,G37,K37,C22,G22,K22,C25,G25,K25,C34,G34,K34) -> 1.5

Sheet PT- Restauración
A2: Elaborado por: Lic. Numa Sebastián Calle Lituma, Esp. Mg. MBA. PhD (c) | H2: Prof. Ronal Chaca Espinoza. Phd | I2: Fuente: Antón; 2016 & Vera Rebollo; 2017
A4: EVALUACIÓN DEL POTENCIAL TURÍSTICO
A5: PLANTA TURÍSTICA
A6: Restauración
A7: Atractivo | D7: Rojo o Ausencia | E7: 0 | H7: Amarillo o Fragilidad | I7: 1 | L7: Verde o Aprovechable | M7: 2
A9: Restaurantes
D10: Ausencia de restaurantes. | G10: 1 | H10: El territorio cuenta con restaurantes de uno y dos tenedores, categorizados y catastrados que cumplen con estándares de servicio básico. Se puede evidenciar la presencia de fondas y sitios de venta de alimentos no catastrados. | L10: El territorio cuenta con restaurantes de tres a cinco tenedores, categorizados y catastrados adecuadamente, cumpliendo estándares de servicio nacional e internacional, se evidencia la presencia de cadenas nacionales y/o internacionales.
A12: Cafeterías
D13: Ausencia de cafeterías. | G13: 1 | H13: El territorio identifica la presencia de negocios orientados a la venta de bebidas calientes y/o frías no alcohólicas no catastradas. | L13: El territorio cuenta con cafeterías de 1 a 2 tazas, catastradas adecuadamente por parte de la Agencia Nacional de Turismo.
A15: Bares
D16: Ausencia de bares. | G16: 1 | H16: El territorio identifica la presencia de negocios orientados a la venta de bebidas alchólicas y/o no alcohólicas no catastradas. | L16: El territorio cuenta con bares de 1 a 3 copas, catastradas adecuadamente por parte de la Agencia Nacional de Turismo.
A18: Discotecas
D19: Ausencia de discotecas. | G19: 1 | H19: El territorio identifica la presencia de negocios orientados a la esparcimiento nocturno con venta de bebidas alchólicas y/o no alcohólicas no catastradas. | L19: El territorio cuenta con bares de 1 a 3 copas, catastradas adecuadamente por parte de la Agencia Nacional de Turismo.
A21: Establecimientos Móviles
D22: Ausencia de establecimientos móviles. | H22: El territorio cuenta con establecimientos itinerantes que elaboran, expenden y/o sirven alimentos fríos y/o calientes, así como bebidas alcohólicas y/o no alcohólicas no catastradas. | K22: 2 | L22: El territorio cuenta con establecimientos móviles debidamente catastrados y categorizados por la Agencia Nacional de Turismo.
A24: Plazas de Comida
D25: Ausencia de plazas de comida. | H25: El territorio cuenta con agrupaciones de prestadores de servicios de alimenos y bebidas, pero no cumplen con los requisitos normativos nacionales y no están catastradas. | K25: 2 | L25: El territorio cuenta con plazas de comida debidamente catastrados y categorizados por la Agencia Nacional de Turismo.
A27: Servicios de Catering
D28: Ausencia de servicios de catering. | H28: Existen empresas de restauración que brindan el servicio como parte de su portafolio. | K28: 2 | L28: Existen empresas y/o personas naturales independientes que ofrecen el servicio en el territorio, cuentan con la LUAF actualizada y están catastrados por la Agencia Nacional de Turismo.
A30: Centro de Turismo Comunitario (Restauración)
D31: El territorio no cuenta con un Centro de Turismo Comunitario. | H31: El territorio cuenta con un centro de turismo comunitario que ofrece servicio de alimentos y bebidas a los visitantes, pero las mismas no se encuentran autorizadas ni catastradas. | K31: 2 | L31: El territorio cuenta con centro de turismo comunitario categorizados y catastrados adecuadamente, que ofrece servicios de alimentos y bebidas, cumpliéndo con lo establecido en el marco normativo nacional respectivo.
D34: Promerio de PT(r) | E34: =AVERAGE(C10,G10,K10,C13,G13,K13,C16,G16,K16,C19,G19,K19,C25,G25,K25,C31,G31,K31,C22,G22,K22,C28,G28,K28) -> 1.5

Sheet PT- Intermediación
A2: Elaborado por: Lic. Numa Sebastián Calle Lituma, Esp. Mg. MBA. PhD (c) | H2: Prof. Ronal Chaca Espinoza. Phd | I2: Fuente: Antón; 2016 & Vera Rebollo; 2017
A4: EVALUACIÓN DEL POTENCIAL TURÍSTICO
A5: PLANTA TURÍSTICA
A6: Intermediación Turística
A7: Atractivo | D7: Rojo o Ausencia | E7: 0 | H7: Amarillo o Fragilidad | I7: 1 | L7: Verde o Aprovechable | M7: 2
A9: Agencias de Viajes Mayoristas
D10: Ausencia de agencias de viaje Mayoirstas. | H10: El territorio presenta actividades de intermediación turística orientada al turismo emisivo informales y no catastradas, orientadas a la venta directa a otras agencias de viaje. | K10: 2 | L10: El territorio cuenta con agencias de viaje mayoristas catastrados adecuadamente y con la LUAF actualizada.
A12: Agencias de Viajes Internacionales
D13: Ausencia de agencias de viaje internacionales. | G13: 1 | H13: El territorio presenta actividades de intermediación turística orientada al turismo emisivo orientadas a la venta directa a los clientes finales de manera informales y no catastradas. | L13: El territorio cuenta con agencias de viaje internacionales catastrados adecuadamente y con la LUAF actualizada.
A15: Operadores Turísticos
D16: Ausencia de operadores turísticos. | H16: El territorio forma parte de los programas turísticos (doméstico y receptivo) ofertados por centros de distribución turística cercanos. | K16: 2 | L16: El territorio cuenta con agencias operadoras de turismo catastrados adecuadamente y con la LUAF actualizada.
A18: Agencias de Viajes Duales
D19: Ausencia de agencias de viajes duales. | H19: El territorio presenta actividades de intermediación turística orientada al turismo emisivo y receptivo orientadas a la venta directa a los clientes finales de manera informales y no catastradas. | K19: 2 | L19: El territorio cuenta con agencias de viaje duales catastrados adecuadamente y con la LUAF actualizada.
A21: Centro de Turismo Comunitario (Operación Turística)
D22: El territorio no cuenta con un Centro de Turismo Comunitario. | H22: El territorio cuenta con un centro de turismo comunitario que ofrece servicio de operación turística a los visitantes, pero las mismas no se encuentran autorizadas ni catastradas. | K22: 2 | L22: El territorio cuenta con centro de turismo comunitario categorizados y catastrados adecuadamente, que ofrece servicios de operación turística, cumpliéndo con lo establecido en el marco normativo nacional respectivo.
D25: Promerio de PT(i) | E25: =AVERAGE(C10,G10,K10,C13,G13,K13,C16,G16,K16,C22,G22,K22,C19,G19,K19) -> 1.8

Sheet PT- Transportación Turística
A2: Elaborado por: Lic. Numa Sebastián Calle Lituma, Esp. Mg. MBA. PhD (c) | H2: Prof. Ronal Chaca Espinoza. Phd | I2: Fuente: Antón; 2016 & Vera Rebollo; 2017
A4: EVALUACIÓN DEL POTENCIAL TURÍSTICO
A5: PLANTA TURÍSTICA
A6: Transportación Mixta y Turística
A7: Atractivo | D7: Rojo o Ausencia | E7: 0 | H7: Amarillo o Fragilidad | I7: 1 | L7: Verde o Aprovechable | M7: 2
A9: Transportación Terrestre por Carretera
D10: Ausencia de transportación terrestre por carretera. | G10: 1 | H10: El territorio cuenta con mecanismos de transportación interna con fines de desplazamiento público y/o comercial. | L10: El territorio cuenta con servicios de transportación terrestre turística por carretera, debidamente categorizadas y con la LUAF activa.
A12: Transportación Terrestre por Ferrocarril
D13: Ausencia de transportación terrestre por ferrocarril. | G13: 1 | H13: El territorio cuenta con sistemas ferroviarios utilizados con finalidades de desplazamiento regular y comercial. | L13: El territorio cuenta con sistemas ferroviarios con fines turísticos, los mismos ofertan itinerarios y rutas aprobadas por los organismos públicos correspondientes.
A15: Transportación Aérea
D16: Ausencia de transportación aérea. | G16: 1 | H16: El territorio cuenta con frecuencias de conectividad aérea con fines comerciales y de carga. | L16: El territorio cuenta con frecuencias aéreashacia el mismo, bajo la negociación comercial denominada "charters".
A18: Transportación Marítima
C19: 0 | D19: Ausencia de transportación marítima. | H19: El territorio cuenta con puertos y embarcaciones que realizan transportación de pasajeros con fines comerciales y de movilidad de pasajeros regulares y carga en entornos marítimos. | L19: El territorio cuenta con puertos de desembarque y embarque de pasajeros de cruceros y/o embarcaciones turísticas debidamente catastradas y con la LUAF activa.
A21: Transportación Fluvial
C22: 0 | D22: Ausencia de transportación fluvial. | H22: El territorio cuenta con puertos y embarcaciones que realizan transportación de pasajeros con fines comerciales y de movilidad de pasajeros regulares y carga en entornos hídricos internos. | L22: El territorio cuenta con servicios de transportación fluvial turística (embarcaciones turísticas), debidamente categorizadas y con la LUAF activa.
A24: Centro de Turismo Comunitario (Transportación Turística)
C25: 0 | D25: El territorio no cuenta con un Centro de Turismo Comunitario. | H25: El territorio cuenta con un centro de turismo comunitario que ofrece servicio de transportación turística a los visitantes, pero las mismas no se encuentran autorizadas ni catastradas. | L25: El territorio cuenta con centro de turismo comunitario categorizados y catastrados adecuadamente, que ofrece servicios de transportación turística, cumpliéndo con lo establecido en el marco normativo nacional respectivo.
D28: Promerio de PT(t) | E28: =AVERAGE(C10,G10,K10,C13,G13,K13,C16,G16,K16,C19,G19,K19,C25,G25,K25,C22,G22,K22) -> 0.5

Sheet PT- Interpretación Turística
A2: Elaborado por: Lic. Numa Sebastián Calle Lituma, Esp. Mg. MBA. PhD (c) | H2: Prof. Ronal Chaca Espinoza. Phd | I2: Fuente: Antón; 2016 & Vera Rebollo; 2017
A4: EVALUACIÓN DEL POTENCIAL TURÍSTICO
A5: PLANTA TURÍSTICA
A6: Interpretación y/o Guianza
A7: Atractivo | D7: Rojo o Ausencia | E7: 0 | H7: Amarillo o Fragilidad | I7: 1 | L7: Verde o Aprovechable | M7: 2
A9: Guías Locales
D10: Ausencia de guías locales. | G10: 1 | H10: Se evidencia la actividad de interpretación por personas de la localidad y/o comunidad que no cuentan con la licencia respectiva (informalidad). | L10: El territorio cuenta con guías locales con una licencia activa y otorgada por la Agencia Nacional de Turismo.
A12: Guías Nacionales
D13: Ausencia de guías nacionales. | H13: Se evidencia la actividad de interpretación turística por personas ajenas al territorio y que no cuentan con la licencia respectiva (informalidad). | K13: 2 | L13: El territorio cuenta con guías nacionales con una licencia activa y otorgada por la Agencia Nacional de Turismo que realizan actividades de interpretación en el sitio.
A15: Guías Especializados en Patrimonio
D16: Ausencia de guías especializados en patrimonio. | G16: 1 | H16: Se evidencia la actividad de interpretación turística por personas ajenas al territorio con importancia natural y/o cultural, y que no cuentan con la licencia respectiva (informalidad). | L16: El territorio cuenta con guías especializados en patrimonio natural y/o cultural con una licencia activa y otorgada por la Agencia Nacional de Turismo que realizan actividades de interpretación en el sitio.
A18: Guías Especializados en Aventura
D19: Ausencia de guías especializados de aventura. | G19: 1 | H19: Se evidencia la actividad de interpretación turística por personas ajenas al territorio en actividades de aventura, y que no cuentan con la licencia respectiva (informalidad). | L19: El territorio cuenta con guías especializados en aventura con una licencia activa y otorgada por la Agencia Nacional de Turismo que realizan actividades de interpretación en el sitio.
D22: Promerio de PT(g) | E22: =AVERAGE(C10,G10,K10,C13,G13,K13,C16,G16,K16,C19,G19,K19) -> 1.25

Sheet TT- Productos Turísticos
A2: Elaborado por: Lic. Numa Sebastián Calle Lituma, Esp. Mg. MBA. PhD (c) | H2: Prof. Ronal Chaca Espinoza. Phd | I2: Fuente: Antón; 2016 & Vera Rebollo; 2017
A4: EVALUACIÓN DEL POTENCIAL TURÍSTICO
A5: PLANTA TURÍSTICA
A6: Productos Turísticos (Reales y/o Potenciales)
A7: Atractivo | D7: Rojo o Ausencia | E7: 0 | H7: Amarillo o Fragilidad | I7: 1 | L7: Verde o Aprovechable | M7: 2
A9: Turismo de Naturaleza
D10: Ausencia de recursos turísticos de naturaleza. | G10: 1 | H10: El territorio cuenta, con recursos turísticos de naturaleza que permiten la realización de actividades turísticas relacionadas y específcas. | L10: El territorio cuenta con recursos turísticos de naturaleza, prestadores de servicios turísticos, infraestructura básica y conectividad al lugar para la realización de actividades relacionadas.
A12: Turismo de Sol y Playa
D13: Ausencia de recursos turísticos de sol y playa. | G13: 1 | H13: El territorio cuenta, con recursos turísticos de sol y playa que permiten la realización de actividades turísticas relacionadas y específicas. | L13: El territorio cuenta con recursos turísticos de sol y playa, prestadores de servicios turísticos, infraestructura básica y conectividad al lugar para la realización de actividades relacionadas.
A15: Turismo Cultural
D16: Ausencia de recursos turísticos culturales. | H16: El territorio cuenta, con recursos turísticos culturales que permiten la realización de actividades turísticas relacionadas y específicas. | K16: 3 | L16: El territorio cuenta con recursos turísticos culturales, prestadores de servicios turísticos, infraestructura básica y conectividad al lugar para la realización de actividades relacionadas.
A18: Turismo Urbano
D19: Ausencia de recursos turísticos urbanos. | G19: 1 | H19: El territorio cuenta, con recursos turísticos urbanos que permiten la realización de actividades turísticas relacionadas y específicas. | L19: El territorio cuenta con recursos turísticos urbanos, prestadores de servicios turísticos, infraestructura básica y conectividad al lugar para la realización de actividades relacionadas.
A21: Turismo Especializado o Alternativo
D22: Ausencia de recursos turísticos que permitan actividades especializadas o alternativas. | G22: 1 | H22: El territorio cuenta, con recursos turísticos que permiten la realización de actividades turísticas especializadas o alternativas. | L22: El territorio cuenta con recursos turísticos especializados o alternativo, prestadores de servicios turísticos, infraestructura básica y conectividad al lugar para la realización de actividades relacionadas. .
A24: Turismo Rural
D25: Ausencia de recursos turísticos de rurales. | G25: 1 | H25: El territorio cuenta, con recursos turísticos rurales que permiten la realización de actividades turísticas relacionadas y específicas. | L25: El territorio cuenta con recursos turísticos rurales, prestadores de servicios turísticos, infraestructura básica y conectividad al lugar para la realización de actividades relacionadas.
A27: Agroturismo
D28: Ausencia de recursos agroturísticos. | G28: 1 | H28: El territorio cuenta, con recursos agroturísticos que permiten la realización de actividades turísticas relacionadas y específicas. | L28: El territorio cuenta con recursos agroturísticos, prestadores de servicios turísticos, infraestructura básica y conectividad al lugar para la realización de actividades relacionadas.
A30: Etnoturismo
D31: Ausencia de recursos etnoturísticos. | G31: 1 | H31: El territorio cuenta, con recursos etnoturísticos que permiten la realización de actividades turísticas relacionadas y específicas.. | L31: El territorio cuenta con recursos etnoturísticos, prestadores de servicios turísticos, infraestructura básica y conectividad al lugar para la realización de actividades relacionadas.
A33: Turismo de Aventura
D34: Ausencia de recursos turísticos que permitan actividades de turismo de aventura. | H34: El territorio cuenta, con recursos turísticos que permiten la realización de actividades turísticas de aventura. | K34: 2 | L34: El territorio cuenta con recursos turísticos, prestadores de servicios turísticos, infraestructura básica y conectividad al lugar para la realización de actividades de aventura.
A36: Turismo Deportivo
D37: Ausencia de recursos turísticos que permitan actividades de turismo deportivo. | H37: El territorio cuenta, con recursos turísticos que permiten la realización de actividades de turismo deportivo. | K37: 2 | L37: El territorio cuenta con recursos turísticos, prestadores de servicios turísticos, infraestructura básica y conectividad al lugar para la realización de actividades de turismo deportivo.
A39: Ecoturismo
D40: Ausencia de recursos ecoturísticos. | H40: El territorio cuenta, con recursos turísticos naturales que permiten la realización de actividades ecoturísticas. | K40: 2 | L40: El territorio cuenta con recursos turísticos de naturaleza, prestadores de servicios turísticos, infraestructura básica y conectividad al lugar para la realización de actividades de ecoturismo.
A42: Turismo de Negocios
D43: Ausencia de recursos turísticos que permitan actividades de turismo de negocios. | H43: El territorio cuenta, con recursos turísticos que permiten la realización de actividades de turismo urbano. | K43: 2 | L43: El territorio cuenta con recursos turísticos, prestadores de servicios turísticos, infraestructura básica y conectividad al lugar para la realización de actividades de turismo de negocios.
A45: Turismo Gastronómico
D46: Ausencia de recursos turísticos gastronómicos. | G46: 1 | H46: El territorio cuenta, con recursos turísticos gastronómicos que permiten la realización de actividades turísticas relacionadas y específicas. | L46: El territorio cuenta con recursos turísticos gastronómicos, prestadores de servicios turísticos, infraestructura básica y conectividad al lugar para la realización de actividades relacionadas.
A48: Turismo Activo
D49: Ausencia de recursos turísticos que permitan actividades de turismo activo. | G49: 1 | H49: El territorio cuenta, con recursos turísticos que permiten la realización de actividades de turismo activo. | L49: El territorio cuenta con recursos turísticos, prestadores de servicios turísticos, infraestructura básica y conectividad al lugar para la realización de actividades de turismo activo.
A51: Turismo Vivencial
D52: Ausencia de recursos turísticos que permitan actividades de turismo vivencial. | G52: 1 | H52: El territorio cuenta, con recursos turísticos que permiten la realización de actividades de turismo vivencial. | L52: El territorio cuenta con recursos turísticos, prestadores de servicios turísticos, infraestructura básica y conectividad al lugar para la realización de actividades de turismo vivencial.
A54: Turismo Experiencial
D55: Ausencia de recursos turísticos que permitan actividades de turismo de experiencial. | G55: 1 | H55: El territorio cuenta, con recursos turísticos que permiten la realización de actividades de turismo experiencial. | L55: El territorio cuenta con recursos turísticos, prestadores de servicios turísticos, infraestructura básica y conectividad al lugar para la realización de actividades de turismo experiencial.
A57: Turismo Patrimonial
D58: Ausencia de recursos turísticos patrimoniales. | H58: El territorio cuenta, con recursos turísticos patrimoniales que permiten la realización de actividades turísticas relacionadas y específicas. | K58: 2 | L58: El territorio cuenta con recursos turísticos patrimoniales, prestadores de servicios turísticos, infraestructura básica y conectividad al lugar para la realización de actividades relacionadas.
A60: Turismo Histórico
...

Sheet I- Infraestructura
A2: Elaborado por: Lic. Numa Sebastián Calle Lituma, Esp. Mg. MBA. PhD (c) | H2: Prof. Ronal Chaca Espinoza. Phd | I2: Fuente: Antón; 2016 & Vera Rebollo; 2017
A4: EVALUACIÓN DEL POTENCIAL TURÍSTICO
A5: INFRAESTRUCTURA
A6: Infraestructra Básica y de Apoyo
A7: Atractivo | D7: Rojo o Ausencia | E7: 0 | H7: Amarillo o Fragilidad | I7: 1 | L7: Verde o Aprovechable | M7: 2
A9: Transporte
D10: El territorio cuenta con servicios de transporte público y privado terrestre. | G10: 1 | H10: El territorio cuenta con servicios de transporte público y privado terrestre y marítimo/fluvial y/o aéreo. | L10: El territorio cuenta con servicios de transporte público y privado terrestre y marítimo/fluvial y aéreo.
A12: Vialidad
D13: El territorio cuenta con caminos de herradura y de tercer orden para llegar a él y recorrerlo. | G13: 1 | H13: El territorio cuenta con caminos de segundo y tercer orden para llegar a él y recorrerlo. | L13: El El territorio cuenta con caminos de primer, segundo y tercer orden para llegar a él y recorrerlo.
A15: Comunicaciones
D16: El territorio no cuenta con servicios de telecomunicaciones a favor de los visitantes. | H16: El territorio cuenta con servicios de telefonía (pública y privada) accesible para la localidad y los visitantes. | K16: 2 | L16: El territorio cuenta con servicio de teléfono público, telefonía local e internet accecible para la localidad y los visitantes.
A18: Salud
D19: El territorio cuenta con dispensarios médicos básicos para atención de los locales. | H19: El territorio cuenta con un centro de salur para atención básica y primaria a favor de la localidad y los visitantes. | K19: 2 | L19: El territorio cuenta con hospitales y centros de salud públicos y privados a disposición de los locales y visitantes.
A21: Energía Eléctirca
D22: Territorio sin servicio de energía eléctria. | H22: Abasto irregular de energía eléctrica doméstica y de alumbrado público con insuficiente cobertura. | K22: 2 | L22: Abasto confiable, eficiente y oportuno de energía eléctrica en todo el territorio.
A24: Agua Potable
C25: 0 | D25: Territorio sin servicio de agua potable. | H25: Limitada cobertura con fuerte deficiencia y fallas en los servicios de agua potable. | L25: Servicios eficientes y con amplia cobertura de las redes de abasto de agua potable en el territorio.
A27: Alcantarillado
C28: 0 | D28: Territorio sin servicio de alcantarillado. | H28: Limitada cobertura de la red de alcantarillado en el territorio, la cual presenta deficiencias reales en la prestación del servicio. | L28: Todo el territorio cuenta con una cobertura amplia y un funcionamiento adecuado de la red de alcantarillado soterrado.
A30: Tratamiento de Basura
C31: 0 | D31: El territorio cuenta con el servicio de recolección de basura y un espacio para recolección y acumulación de desperdicios. | H31: El territorio cuenta con el servicio de recolección de basura de por lo menos una vez a la semana, tratamiento básico de desechos y botadero de basura básico. | L31: El territorio cuenta con el servicio de recolección de basura de por lo menos dos veces a la semana, tratamiento de desechos y botadero de basura que cumple con estándares ambientales.
A33: Tratamiento de Aguas Residuales
C34: 0 | D34: Territorio sin servicio de tratamiento de aguas residuales. | H34: Limitada cobertura en la red de tratamiento de aguas residuales en el territorio, se evidencian falencias en su operatividad. | L34: El territorio demuestra una cobertura total para el tratamiento de aguas residuales con un funcionamiento adecuado y eficiente.
A36: Conectividad
C37: 0 | D37: El territorio cuenta con espacios con acondicionamiento básico de ingreso de visitantes por vía terrestre. | H37: El territorio cuenta con terminal terrestre y aeropuertos o puertos para la llegada de los visitantes. | L37: El territorio cuenta con terminal terrestre, aeropuertos y puertos para la llegada de los visitantes.
A39: Señalización
D40: El territorio cuenta con señalización vial para llegar a él pero no con señalización dentro del sitio. | G40: 1 | H40: El territorio cuenta con señalización vial para llegar a él y dentro del sitio. | L40: El territorio cuenta con señalización vial y turística para llegar a él y recorrer de manera eficiente el sitio.
D43: Promerio de I | E43: =AVERAGE(C10,G10,K10,C13,G13,K13,C16,G16,K16,C22,G22,K22,C25,G25,K25,C28,G28,K28,C31,G31,K31,C34,G34,K34,C19,G19,K19,C37,G37,K37,C40,G40,K40) -> 0.81818182

Sheet DT- Afluencia Turística 
A2: Elaborado por: Lic. Numa Sebastián Calle Lituma, Esp. Mg. MBA. PhD (c) | H2: Prof. Ronal Chaca Espinoza. Phd | I2: Fuente: Antón; 2016 & Vera Rebollo; 2017
A4: EVALUACIÓN DEL POTENCIAL TURÍSTICO
A5: DEMANDA TURÍSTICA
A6: Flujos Turísticos o Afluencia Turística
A7: Atractivo | D7: Rojo o Ausencia | E7: 0 | H7: Amarillo o Fragilidad | I7: 1 | L7: Verde o Aprovechable | M7: 2
A9: Flujos Turísticos Locales
D10: El destino no cuenta con visitación turística de visitantes locales. | G10: 1 | H10: Visitas ocacionales y/o de paso en el territorio por encontrarse en la trayectoria hacia otros destinos. | L10: El territorio cuenta con visitación turística local evidenciable directo en el sitio.
A12: Flujos Turísticos Regionales
D13: El destino no cuenta con visitación turística de visitantes regionales. | H13: Visitas ocacionales y/o de paso en el territorio por encontrarse en la trayectoria hacia otros destinos. | K13: 2 | L13: El territorio cuenta con visitación turística regional evidenciable directo en el sitio.
A15: Flujos Turísticos Nacionales
D16: El destino no cuenta con visitación turística de visitantes nacionales. | G16: 1 | H16: Visitas ocacionales y/o de paso en el territorio por encontrarse en la trayectoria hacia otros destinos. | L16: El territorio cuenta con visitación turística nacional evidenciable directo en el sitio.
A18: Flujos Turísticos Internacionales
D19: El destino no cuenta con visitación turística de visitantes internacionales. | G19: 1 | H19: Visitas ocacionales y/o de paso en el territorio por encontrarse en la trayectoria hacia otros destinos. | L19: El territorio cuenta con visitación turística internacional evidenciable directo en el sitio.
A21: Estadía Promedio
D22: El territorio presenta un periodo de estancia inferior a 24 horas. | G22: 1 | H22: El territorio presenta un periodo de estancia superior a 24 horas e inferior a 72 horas | L22: El territorio presenta un periodo de estancia superior a 72 horas
D25: Promerio de DT(at) | E25: =AVERAGE(C10,G10,K10,C13,G13,K13,C22,G22,K22,C16,G16,K16) -> 1.25

Sheet DT- Marketing Turístico
A2: Elaborado por: Lic. Numa Sebastián Calle Lituma, Esp. Mg. MBA. PhD (c) | H2: Prof. Ronal Chaca Espinoza. Phd | I2: Fuente: Antón; 2016 & Vera Rebollo; 2017
A4: EVALUACIÓN DEL POTENCIAL TURÍSTICO
A5: DEMANDA TURÍSTICA
A6: Marketing Turístico
A7: Atractivo | D7: Rojo o Ausencia | E7: 0 | H7: Amarillo o Fragilidad | I7: 1 | L7: Verde o Aprovechable | M7: 2
A9: Organismo Público Promotor
D10: El territorio no cuenta con profesionales encargado de la actividad turística. | H10: El territorio cuenta con profesionales en otras áreas del conocimiento encargados de la actividad turística. | K10: 2 | L10: El territorio cuenta con un departamento encargado del desarrollo y control de la actividad turística en el sitio.
A12: Plan de Marketing Asociado
D13: El territorio no cuenta con un plan de marketing propio y/o asociado. | H13: El territorio cuenta con un plan de marketing asociado a un plan estratégico establecido para un territorio mayor. | K13: 2 | L13: El territorio cuenta con un plan de marketing propio que aborde los requerimientos específicos del sitio.
A15: Tendencias de Mercado Actuales
D16: El territorio no cuenta con recursos turísticos que se puedan utilizar para ajustarlos a los requerimientos de las tendencias de mercado. | H16: El territorio cuenta con recursos turísticos que se puedan utilizar para ajustarlos a los requerimientos de las tendencias de mercado, pero no se ha generado el ajuste de la oferta. | K16: 2 | L16: El territorio cuenta con atractivos turísticos, equipamiento e infraestructura de apoyo para poder adaptar su oferta a las tendencias de mercado.
A18: Investigación y Segmentación de Mercados
D19: El territorio no cuenta con información primaria y secundaria referente a los visitantes del sitio. | G19: 1 | H19: El territorio cuenta con información secundaria referente a los visitantes del sitio. | L19: El territorio cuenta con información primaria y secundaria relevante referente a los visitantes del sitio.
A21: Publicidad y Promoción
D22: El territorio no cuenta publicidad y/o promoción tradicional o disruptiva propia. | H22: El territorio cuenta con publicidad y/o promoción tradicional referente al patrimonio turístico del sitio. | K22: 2 | L22: El territorio cuenta con publicidad y/o promoción tradicional y disruptiva referente al patrimonio turístico del sitio.
A24: Comercialización Turística Tradicional
D25: El territorio no cuenta con intermediadores de mercado en el sitio. | G25: 1 | H25: El territorio forma parte de la oferta de turismo de la provincia y/o cantón ofrecida por parte de los intermediadiores de mercado del territorio adyacente. | L25: El territorio cuenta con intermediadores de mercado en el sitio y además forma parte de la oferta turística generada por intermediadores nacionales.
A27: Comercialización Turística Digital
D28: El territorio no cuenta con intermediadores de mercado digitales en el sitio. | H28: El territorio forma parte de la oferta turística de la provincio y/o cantón ofrecida de forma digital por parte de los intermediadores de mercado adyacentes. | K28: 2 | L28: El territorio cuenta con intermediadores de mercado con oferta digital en el sitio y además forma parte de la oferta digital de los intermediadores nacionales.
A30: Imagen del Sitio
D31: El territorio no cuenta con una imagen distintiva, diferenciadora, representativa y con posicionamiento local. | G31: 1 | H31: El territorio cuenta con una imagen distintiva, poco diferenciadora y con un posicionamiento nacional. | L31: El territorio cuenta con una imagen distintiva, diferenciadora, representativa y con un posicionamiento internacional.
A33: Presencia Digital
D34: El territorio no cuenta con presencia digital (página web, blogs de viaje, redes sociales) | G34: 1 | H34: El territorio tiene presencia en redes sociales con información relevante en el ámbito del turismo. | L34: El territorio cuenta con una página web propia y redes sociales, relacionadas directamente con el ámbito del turismo.
A36: Innovación Turística
D37: No se evidencia un proceso de innovación en la oferta de productos y servicios turísticos en el territorio. | G37: 1 | H37: Se evidencia la generación y apoyo para la innovación turística en la prestación de servicios característicos y relacionados con el turismo. | L37: Se evidencia la generación y apoyo en los procesos de innovación turística para la prestación de servicios turísticos (característicos y relacionados) y el diseño de productos turísticos en el sitio.
D40: Promerio de DT(mk) | E40: =AVERAGE(C10,G10,K10,C13,G13,K13,C16,G16,K16,C19,G19,K19,C25,G25,K25,C28,G28,K28,C34,G34,K34,C37,G37,K37,C22,G22,K22,C31,G31,K31) -> 1.5

Sheet ST- Superestructura del Turismo
A2: Elaborado por: Lic. Numa Sebastián Calle Lituma, Esp. Mg. MBA. PhD (c) | H2: Prof. Ronal Chaca Espinoza. Phd | I2: Fuente: Antón; 2016 & Vera Rebollo; 2017
A4: EVALUACIÓN DEL POTENCIAL TURÍSTICO
A5: SUPERESTRUCTURA DEL TURISMO
A6: Gestión Pública, Gobernanza Turística, Gobernabilidad, Política Turística, entre otras.
A7: Atractivo | D7: Rojo o Ausencia | E7: 0 | H7: Amarillo o Fragilidad | I7: 1 | L7: Verde o Aprovechable | M7: 2
A9: Política Pública de Turismo
D10: Ausencia de políticas públicas para el desarrollo y/o fomento turístico. | G10: 1 | H10: Presencia de políticas públicas relacionadas con el cuidado y la conservación del patrimonio y el medio ambiente. | L10: Evidencia clara de la existencia de una política pública de turísmo orientada a desarrollar y/o fomentar competitivamente el turismo en el territorio.
A12: Modelo de Gestión Turística
D13: Ausencia de modelos de gestión turística evidenciados en el territorio. | H13: Evidencia de un modelo de gestión turística del territorio desactualizado y poco técnico. | K13: 2 | L13: Modelo de gestión turística territorial eficiente y eficaz adecuado para el territorio.
A15: Actores de la Actividad Turística
D16: Ausencia de prestadores de servicios turísticos en el territorio. | H16: Precencia limitada y poco diferenciada de prestadores de servicios turísticos en el territorio. | K16: 2 | L16: Presencia diversificada de prestadores de servicios turísticos en dieversas actividades turísticas en el territorio.
A18: Marco Normativo
D19: Inexistensia de un marco legal regulatorio relacionado con el ámbito turístico. | G19: 1 | H19: Ineficiente aplicación de los marcos normativos relacionados con la actividad turística en el territorio. | L19: Marco normativo aplicado en el territorio de forma adecuada y eficiente.
A21: Participación Ciudadana
D22: Nula participación ciudadana en los procesos de planificación, gestión y comercialización de la actividad turística en el territorio. | G22: 1 | H22: Procesos de participación ciudadana incompatibles y centralizados sin tomar en cuenta a la localidad y a todos los actores del territorio. | L22: Procesos de participación ciudadana establecidos, normativizados y socializados entre todos los actores del turismo en el territorio.
A24: Planificación Participativa
D25: Procesos de planificación arcáicos para el desarrollo y fortalecimiento de la actividad turística en el territorio. | G25: 1 | H25: Procesos de planificación básicos sin un enfoque(s) definido, el análisis del sistema turístico es básico y limitado; además se evidencia la poca adaptación a la realidad territorial. | L25: Procesos de planificación con enfoques, modelos, sistemas y actores bien definidos y adaptados con la realidad territorial.
A27: Entes públicos encargados del Turismo
D28: Ausencia de un ente público encargado del desarrollo y fomento turístico en el territorio. | G28: 1 | H28: El territorio no cuenta con un área o departamento encargada de regular, controlar y apoyar en los procesos de desarrollo y fomento turístico en el lugar; pero esta adscrito al territorio de mayor jerarquía de organización territorial a la que pertenece. | L28: El territorio cuenta con un área o departamento encargada de regular, controlar y apoyar en los procesos de desarrollo y fomento turístico en el lugar.
A30: Representación Gremial y asociaciones turísticas
D31: Inexistencia de agremiaciones o representaciones de los actores privados y comunitarios. | G31: 1 | H31: Existencia de agremiaciones y asociaciones turísticas limitadas con relación a las actividades de turismo establecidas en la normativa nacional. | L31: Existencia de agremiaciones y asociaciones en turismo diversar que cumplen con los lineamientos normativos nacionales e internacionales.
A33: Representatividad Comunitaria
D34: Ausencia de representaciones comunitarias en el territorio (organizaciones, líderes comunitarios, etc.). | G34: 1 | H34: El territorio cuenta con un líder comunitario, que forma parte de los procesos de desarrollo de la localidad pero con marcados interéses establecidos. | L34: El territorio cuenta con un líder comunitario y una organización comunitaria establecida y reconocida legalmente que demuestran interés en el ámbito turístico, formando parte activa de los procesos relacionados.
A36: Fomento al Sector Turístico
D37: Ausencia de líneas de fomento y apoyo al mejoramiento y crecimiento de la actividad turística en el territorio. | G37: 1 | H37: Los componentes del sistema turístico del territorio puede acceder a líneas de fomento en proyectos con viabilidad económica que propendan a la mejora continua del sector turístico. | L37: El territorio cuenta con líneas de fomento turístico con estrategias claramente definidas que mejoren la calidad de vida de la localidad y la economía del territorio; brindadas por instituciones públicas y privadas diferenciadas para cada unos de los prestadores de servicios turísticos.
